<?xml version="1.0"?>
<robot name="robo">

  <!-- 1. Podstawa -->
  <link name="base_link">
    <visual>
      <origin xyz="0 0 0.0225" rpy="0 0 0"/>
      <geometry>
        <cylinder length="0.050" radius="0.089"/>
      </geometry>
    </visual>
  </link>

  <joint name="base_joint" type="revolute">
    <parent link="base_link"/>
    <child link="base_rot"/>
    <origin xyz="0 0 0.072" rpy="0 0 0"/>
    <axis xyz="0 0 -1"/>
  </joint>

  <link name="base_rot">
    <visual>
      <geometry>
        <box size="0.05 0.05 0.053"/>
      </geometry>
    </visual>
  </link>

  <joint name="shoulder_joint" type="revolute">
    <parent link="base_rot"/>
    <child link="arm1"/>
    <origin xyz="0 0 0.027" rpy="0 0 0"/>
    <axis xyz="1 0 0"/>
    <limit lower="-1.57" upper="1.57"/>
  </joint>

  <link name="arm1">
    <visual>
      <origin xyz="0 0 0.119" rpy="0 0 0"/>
      <geometry>
        <cylinder length="0.238" radius="0.022"/>
      </geometry>
    </visual>
  </link>

  <joint name="elbow_joint" type="revolute">
    <parent link="arm1"/>
    <child link="arm2"/>
    <origin xyz="0 0 0.238" rpy="0 0 0"/>
    <axis xyz="1 0 0"/>
    <limit lower="-1.92" upper="1.92"/>
  </joint>

  <link name="arm2">
    <visual>
      <origin xyz="0 0 0.075" rpy="0 0 0"/>
      <geometry>
        <cylinder length="0.150" radius="0.0175"/>
      </geometry>
    </visual>
  </link>

  <joint name="rot_joint" type="revolute">
    <parent link="arm2"/>
    <child link="tilt"/>
    <origin xyz="0 0 0.15" rpy="0 0 0"/>
    <axis xyz="0 0 -1"/>
    <limit lower="-1.57" upper="2.8"/>
  </joint>


</robot>